<?xml version="1.0" encoding="UTF-8"?>
<testng-results skipped="0" failed="3" ignored="0" total="6" passed="3">
  <reporter-output>
  </reporter-output>
  <suite name="Default suite" duration-ms="93" started-at="2018-02-16T14:20:52Z" finished-at="2018-02-16T14:20:52Z">
    <groups>
    </groups>
    <test name="Default test" duration-ms="93" started-at="2018-02-16T14:20:52Z" finished-at="2018-02-16T14:20:52Z">
      <class name="cs265.CS265_Lab1Test">
        <test-method status="PASS" signature="method1_test1()[pri:0, instance:cs265.CS265_Lab1Test@5d5eef3d]" name="method1_test1" duration-ms="20" started-at="2018-02-16T14:20:52Z" finished-at="2018-02-16T14:20:52Z">
          <reporter-output>
          </reporter-output>
        </test-method> <!-- method1_test1 -->
        <test-method status="PASS" signature="method1_test2()[pri:0, instance:cs265.CS265_Lab1Test@5d5eef3d]" name="method1_test2" duration-ms="1" started-at="2018-02-16T14:20:52Z" finished-at="2018-02-16T14:20:52Z">
          <reporter-output>
          </reporter-output>
        </test-method> <!-- method1_test2 -->
        <test-method status="FAIL" signature="method1_test3()[pri:0, instance:cs265.CS265_Lab1Test@5d5eef3d]" name="method1_test3" duration-ms="1" started-at="2018-02-16T14:20:52Z" finished-at="2018-02-16T14:20:52Z">
          <exception class="java.lang.AssertionError">
            <message>
              <![CDATA[expected:<-55> but was:<-1>]]>
            </message>
            <full-stacktrace>
              <![CDATA[java.lang.AssertionError: expected:<-55> but was:<-1>at org.testng.AssertJUnit.fail(AssertJUnit.java:59)at org.testng.AssertJUnit.failNotEquals(AssertJUnit.java:364)at org.testng.AssertJUnit.assertEquals(AssertJUnit.java:80)at org.testng.AssertJUnit.assertEquals(AssertJUnit.java:245)at org.testng.AssertJUnit.assertEquals(AssertJUnit.java:252)at cs265.CS265_Lab1Test.method1_test3(CS265_Lab1Test.java:21)at sun.reflect.NativeMethodAccessorImpl.invoke0(Native Method)at sun.reflect.NativeMethodAccessorImpl.invoke(Unknown Source)at sun.reflect.DelegatingMethodAccessorImpl.invoke(Unknown Source)at java.lang.reflect.Method.invoke(Unknown Source)at org.testng.internal.MethodInvocationHelper.invokeMethod(MethodInvocationHelper.java:124)at org.testng.internal.Invoker.invokeMethod(Invoker.java:571)at org.testng.internal.Invoker.invokeTestMethod(Invoker.java:707)at org.testng.internal.Invoker.invokeTestMethods(Invoker.java:979)at org.testng.internal.TestMethodWorker.invokeTestMethods(TestMethodWorker.java:125)at org.testng.internal.TestMethodWorker.run(TestMethodWorker.java:109)at org.testng.TestRunner.privateRun(TestRunner.java:648)at org.testng.TestRunner.run(TestRunner.java:505)at org.testng.SuiteRunner.runTest(SuiteRunner.java:455)at org.testng.SuiteRunner.runSequentially(SuiteRunner.java:450)at org.testng.SuiteRunner.privateRun(SuiteRunner.java:415)at org.testng.SuiteRunner.run(SuiteRunner.java:364)at org.testng.SuiteRunnerWorker.runSuite(SuiteRunnerWorker.java:52)at org.testng.SuiteRunnerWorker.run(SuiteRunnerWorker.java:84)at org.testng.TestNG.runSuitesSequentially(TestNG.java:1187)at org.testng.TestNG.runSuitesLocally(TestNG.java:1116)at org.testng.TestNG.runSuites(TestNG.java:1028)at org.testng.TestNG.run(TestNG.java:996)at org.testng.remote.AbstractRemoteTestNG.run(AbstractRemoteTestNG.java:114)at org.testng.remote.RemoteTestNG.initAndRun(RemoteTestNG.java:251)at org.testng.remote.RemoteTestNG.main(RemoteTestNG.java:77)]]>
            </full-stacktrace>
          </exception> <!-- java.lang.AssertionError -->
          <reporter-output>
          </reporter-output>
        </test-method> <!-- method1_test3 -->
        <test-method status="PASS" signature="method1_test4()[pri:0, instance:cs265.CS265_Lab1Test@5d5eef3d]" name="method1_test4" duration-ms="1" started-at="2018-02-16T14:20:52Z" finished-at="2018-02-16T14:20:52Z">
          <reporter-output>
          </reporter-output>
        </test-method> <!-- method1_test4 -->
        <test-method status="FAIL" signature="method1_test5()[pri:0, instance:cs265.CS265_Lab1Test@5d5eef3d]" name="method1_test5" duration-ms="2" started-at="2018-02-16T14:20:52Z" finished-at="2018-02-16T14:20:52Z">
          <exception class="java.lang.AssertionError">
            <message>
              <![CDATA[expected:<81> but was:<-1>]]>
            </message>
            <full-stacktrace>
              <![CDATA[java.lang.AssertionError: expected:<81> but was:<-1>at org.testng.AssertJUnit.fail(AssertJUnit.java:59)at org.testng.AssertJUnit.failNotEquals(AssertJUnit.java:364)at org.testng.AssertJUnit.assertEquals(AssertJUnit.java:80)at org.testng.AssertJUnit.assertEquals(AssertJUnit.java:245)at org.testng.AssertJUnit.assertEquals(AssertJUnit.java:252)at cs265.CS265_Lab1Test.method1_test5(CS265_Lab1Test.java:31)at sun.reflect.NativeMethodAccessorImpl.invoke0(Native Method)at sun.reflect.NativeMethodAccessorImpl.invoke(Unknown Source)at sun.reflect.DelegatingMethodAccessorImpl.invoke(Unknown Source)at java.lang.reflect.Method.invoke(Unknown Source)at org.testng.internal.MethodInvocationHelper.invokeMethod(MethodInvocationHelper.java:124)at org.testng.internal.Invoker.invokeMethod(Invoker.java:571)at org.testng.internal.Invoker.invokeTestMethod(Invoker.java:707)at org.testng.internal.Invoker.invokeTestMethods(Invoker.java:979)at org.testng.internal.TestMethodWorker.invokeTestMethods(TestMethodWorker.java:125)at org.testng.internal.TestMethodWorker.run(TestMethodWorker.java:109)at org.testng.TestRunner.privateRun(TestRunner.java:648)at org.testng.TestRunner.run(TestRunner.java:505)at org.testng.SuiteRunner.runTest(SuiteRunner.java:455)at org.testng.SuiteRunner.runSequentially(SuiteRunner.java:450)at org.testng.SuiteRunner.privateRun(SuiteRunner.java:415)at org.testng.SuiteRunner.run(SuiteRunner.java:364)at org.testng.SuiteRunnerWorker.runSuite(SuiteRunnerWorker.java:52)at org.testng.SuiteRunnerWorker.run(SuiteRunnerWorker.java:84)at org.testng.TestNG.runSuitesSequentially(TestNG.java:1187)at org.testng.TestNG.runSuitesLocally(TestNG.java:1116)at org.testng.TestNG.runSuites(TestNG.java:1028)at org.testng.TestNG.run(TestNG.java:996)at org.testng.remote.AbstractRemoteTestNG.run(AbstractRemoteTestNG.java:114)at org.testng.remote.RemoteTestNG.initAndRun(RemoteTestNG.java:251)at org.testng.remote.RemoteTestNG.main(RemoteTestNG.java:77)]]>
            </full-stacktrace>
          </exception> <!-- java.lang.AssertionError -->
          <reporter-output>
          </reporter-output>
        </test-method> <!-- method1_test5 -->
        <test-method status="FAIL" signature="method1_test6()[pri:0, instance:cs265.CS265_Lab1Test@5d5eef3d]" name="method1_test6" duration-ms="4" started-at="2018-02-16T14:20:52Z" finished-at="2018-02-16T14:20:52Z">
          <exception class="java.lang.AssertionError">
            <message>
              <![CDATA[expected:<12> but was:<15>]]>
            </message>
            <full-stacktrace>
              <![CDATA[java.lang.AssertionError: expected:<12> but was:<15>at org.testng.AssertJUnit.fail(AssertJUnit.java:59)at org.testng.AssertJUnit.failNotEquals(AssertJUnit.java:364)at org.testng.AssertJUnit.assertEquals(AssertJUnit.java:80)at org.testng.AssertJUnit.assertEquals(AssertJUnit.java:245)at org.testng.AssertJUnit.assertEquals(AssertJUnit.java:252)at cs265.CS265_Lab1Test.method1_test6(CS265_Lab1Test.java:36)at sun.reflect.NativeMethodAccessorImpl.invoke0(Native Method)at sun.reflect.NativeMethodAccessorImpl.invoke(Unknown Source)at sun.reflect.DelegatingMethodAccessorImpl.invoke(Unknown Source)at java.lang.reflect.Method.invoke(Unknown Source)at org.testng.internal.MethodInvocationHelper.invokeMethod(MethodInvocationHelper.java:124)at org.testng.internal.Invoker.invokeMethod(Invoker.java:571)at org.testng.internal.Invoker.invokeTestMethod(Invoker.java:707)at org.testng.internal.Invoker.invokeTestMethods(Invoker.java:979)at org.testng.internal.TestMethodWorker.invokeTestMethods(TestMethodWorker.java:125)at org.testng.internal.TestMethodWorker.run(TestMethodWorker.java:109)at org.testng.TestRunner.privateRun(TestRunner.java:648)at org.testng.TestRunner.run(TestRunner.java:505)at org.testng.SuiteRunner.runTest(SuiteRunner.java:455)at org.testng.SuiteRunner.runSequentially(SuiteRunner.java:450)at org.testng.SuiteRunner.privateRun(SuiteRunner.java:415)at org.testng.SuiteRunner.run(SuiteRunner.java:364)at org.testng.SuiteRunnerWorker.runSuite(SuiteRunnerWorker.java:52)at org.testng.SuiteRunnerWorker.run(SuiteRunnerWorker.java:84)at org.testng.TestNG.runSuitesSequentially(TestNG.java:1187)at org.testng.TestNG.runSuitesLocally(TestNG.java:1116)at org.testng.TestNG.runSuites(TestNG.java:1028)at org.testng.TestNG.run(TestNG.java:996)at org.testng.remote.AbstractRemoteTestNG.run(AbstractRemoteTestNG.java:114)at org.testng.remote.RemoteTestNG.initAndRun(RemoteTestNG.java:251)at org.testng.remote.RemoteTestNG.main(RemoteTestNG.java:77)]]>
            </full-stacktrace>
          </exception> <!-- java.lang.AssertionError -->
          <reporter-output>
          </reporter-output>
        </test-method> <!-- method1_test6 -->
      </class> <!-- cs265.CS265_Lab1Test -->
    </test> <!-- Default test -->
  </suite> <!-- Default suite -->
</testng-results>
